<?xml version="1.0" encoding="UTF-8"?>
<testng-results skipped="0" failed="1" total="1" passed="0">
  <reporter-output>
  </reporter-output>
  <suite name="Suite" duration-ms="26046" started-at="2022-02-28T06:10:36Z" finished-at="2022-02-28T06:11:02Z">
    <groups>
    </groups>
    <test name="Test" duration-ms="26046" started-at="2022-02-28T06:10:36Z" finished-at="2022-02-28T06:11:02Z">
      <class name="testScripts.TestScriptLogin">
        <test-method status="PASS" signature="before()[pri:0, instance:testScripts.TestScriptLogin@16c0663d]" name="before" is-config="true" duration-ms="12034" started-at="2022-02-28T11:40:36Z" finished-at="2022-02-28T11:40:48Z">
          <reporter-output>
          </reporter-output>
        </test-method> <!-- before -->
        <test-method status="FAIL" signature="test()[pri:0, instance:testScripts.TestScriptLogin@16c0663d]" name="test" duration-ms="6742" started-at="2022-02-28T11:40:48Z" finished-at="2022-02-28T11:40:55Z">
          <exception class="java.lang.AssertionError">
            <message>
              <![CDATA[null]]>
            </message>
            <full-stacktrace>
              <![CDATA[java.lang.AssertionError: null
	at org.testng.Assert.fail(Assert.java:94)
	at org.testng.Assert.fail(Assert.java:101)
	at testScripts.TestScriptLogin.test(TestScriptLogin.java:25)
	at sun.reflect.NativeMethodAccessorImpl.invoke0(Native Method)
	at sun.reflect.NativeMethodAccessorImpl.invoke(Unknown Source)
	at sun.reflect.DelegatingMethodAccessorImpl.invoke(Unknown Source)
	at java.lang.reflect.Method.invoke(Unknown Source)
	at org.testng.internal.MethodInvocationHelper.invokeMethod(MethodInvocationHelper.java:86)
	at org.testng.internal.Invoker.invokeMethod(Invoker.java:645)
	at org.testng.internal.Invoker.invokeTestMethod(Invoker.java:822)
	at org.testng.internal.Invoker.invokeTestMethods(Invoker.java:1130)
	at org.testng.internal.TestMethodWorker.invokeTestMethods(TestMethodWorker.java:129)
	at org.testng.internal.TestMethodWorker.run(TestMethodWorker.java:112)
	at org.testng.TestRunner.privateRun(TestRunner.java:782)
	at org.testng.TestRunner.run(TestRunner.java:632)
	at org.testng.SuiteRunner.runTest(SuiteRunner.java:366)
	at org.testng.SuiteRunner.runSequentially(SuiteRunner.java:361)
	at org.testng.SuiteRunner.privateRun(SuiteRunner.java:319)
	at org.testng.SuiteRunner.run(SuiteRunner.java:268)
	at org.testng.SuiteRunnerWorker.runSuite(SuiteRunnerWorker.java:52)
	at org.testng.SuiteRunnerWorker.run(SuiteRunnerWorker.java:86)
	at org.testng.TestNG.runSuitesSequentially(TestNG.java:1244)
	at org.testng.TestNG.runSuitesLocally(TestNG.java:1169)
	at org.testng.TestNG.run(TestNG.java:1064)
	at org.testng.remote.RemoteTestNG.run(RemoteTestNG.java:113)
	at org.testng.remote.RemoteTestNG.initAndRun(RemoteTestNG.java:206)
	at org.testng.remote.RemoteTestNG.main(RemoteTestNG.java:177)
]]>
            </full-stacktrace>
          </exception> <!-- java.lang.AssertionError -->
          <reporter-output>
          </reporter-output>
        </test-method> <!-- test -->
        <test-method status="PASS" signature="after(org.testng.ITestResult)[pri:0, instance:testScripts.TestScriptLogin@16c0663d]" name="after" is-config="true" duration-ms="7247" started-at="2022-02-28T11:40:55Z" finished-at="2022-02-28T11:41:02Z">
          <params>
            <param index="0">
              <value>
                <![CDATA[[TestResult name=test status=FAILURE method=TestScriptLogin.test()[pri:0, instance:testScripts.TestScriptLogin@16c0663d] output={null}]]]>
              </value>
            </param>
          </params>
          <reporter-output>
          </reporter-output>
        </test-method> <!-- after -->
      </class> <!-- testScripts.TestScriptLogin -->
    </test> <!-- Test -->
  </suite> <!-- Suite -->
</testng-results>
